reported_result/report-8/ART_TFC/output/output4.txt

Limit	1	1	7	8	5	SELL	0	---	0
NewOrderRs	Accepted
	Trades	0
	Orders	1
	Order	Limit	1	1	7	8	5	SELL	0	---	0
	Credits	7
	Credit	1	8
	Credit	2	6
	Credit	3	5
	Credit	4	8
	Credit	5	11
	Credit	6	12
	Credit	7	4
	Ownerships	7
	Ownership	1	25
	Ownership	2	49
	Ownership	3	29
	Ownership	4	19
	Ownership	5	52
	Ownership	6	94
	Ownership	7	83
	ReferencePrice	5
	StaticPriceBandLowerLimit	0.6
	StaticPriceBandUpperLimit	0.8
	TotalShares	100
	OwnershipUpperLimit	0.2
	TickSize	1
	LotSize	1
Limit	2	6	3	9	1	BUY 	0	---	0
NewOrderRs	Rejected
	Trades	0
	Orders	1
	Order	Limit	1	1	7	8	5	SELL	0	---	0
	Credits	7
	Credit	1	8
	Credit	2	6
	Credit	3	5
	Credit	4	8
	Credit	5	11
	Credit	6	12
	Credit	7	4
	Ownerships	7
	Ownership	1	25
	Ownership	2	49
	Ownership	3	29
	Ownership	4	19
	Ownership	5	52
	Ownership	6	94
	Ownership	7	83
	ReferencePrice	5
	StaticPriceBandLowerLimit	0.6
	StaticPriceBandUpperLimit	0.8
	TotalShares	100
	OwnershipUpperLimit	0.2
	TickSize	1
	LotSize	1
Limit	3	1	1	9	1	SELL	0	---	0
NewOrderRs	Accepted
	Trades	0
	Orders	2
	Order	Limit	1	1	7	8	5	SELL	0	---	0
	Order	Limit	3	1	1	9	1	SELL	0	---	0
	Credits	7
	Credit	1	8
	Credit	2	6
	Credit	3	5
	Credit	4	8
	Credit	5	11
	Credit	6	12
	Credit	7	4
	Ownerships	7
	Ownership	1	25
	Ownership	2	49
	Ownership	3	29
	Ownership	4	19
	Ownership	5	52
	Ownership	6	94
	Ownership	7	83
	ReferencePrice	5
	StaticPriceBandLowerLimit	0.6
	StaticPriceBandUpperLimit	0.8
	TotalShares	100
	OwnershipUpperLimit	0.2
	TickSize	1
	LotSize	1
Limit	4	3	3	9	8	SELL	0	FAK	0
NewOrderRs	Eliminated
	Trades	0
	Orders	2
	Order	Limit	1	1	7	8	5	SELL	0	---	0
	Order	Limit	3	1	1	9	1	SELL	0	---	0
	Credits	7
	Credit	1	8
	Credit	2	6
	Credit	3	5
	Credit	4	8
	Credit	5	11
	Credit	6	12
	Credit	7	4
	Ownerships	7
	Ownership	1	25
	Ownership	2	49
	Ownership	3	29
	Ownership	4	19
	Ownership	5	52
	Ownership	6	94
	Ownership	7	83
	ReferencePrice	5
	StaticPriceBandLowerLimit	0.6
	StaticPriceBandUpperLimit	0.8
	TotalShares	100
	OwnershipUpperLimit	0.2
	TickSize	1
	LotSize	1
CancelOrderRs	Rejected
	Orders	2
	Order	Limit	1	1	7	8	5	SELL	0	---	0
	Order	Limit	3	1	1	9	1	SELL	0	---	0
	Credits	7
	Credit	1	8
	Credit	2	6
	Credit	3	5
	Credit	4	8
	Credit	5	11
	Credit	6	12
	Credit	7	4
	Ownerships	7
	Ownership	1	25
	Ownership	2	49
	Ownership	3	29
	Ownership	4	19
	Ownership	5	52
	Ownership	6	94
	Ownership	7	83
	ReferencePrice	5
	StaticPriceBandLowerLimit	0.6
	StaticPriceBandUpperLimit	0.8
	TotalShares	100
	OwnershipUpperLimit	0.2
	TickSize	1
	LotSize	1
Limit	6	3	2	4	6	SELL	0	---	0
NewOrderRs	Accepted
	Trades	0
	Orders	3
	Order	Limit	6	3	2	4	6	SELL	0	---	0
	Order	Limit	1	1	7	8	5	SELL	0	---	0
	Order	Limit	3	1	1	9	1	SELL	0	---	0
	Credits	7
	Credit	1	8
	Credit	2	6
	Credit	3	5
	Credit	4	8
	Credit	5	11
	Credit	6	12
	Credit	7	4
	Ownerships	7
	Ownership	1	25
	Ownership	2	49
	Ownership	3	29
	Ownership	4	19
	Ownership	5	52
	Ownership	6	94
	Ownership	7	83
	ReferencePrice	5
	StaticPriceBandLowerLimit	0.6
	StaticPriceBandUpperLimit	0.8
	TotalShares	100
	OwnershipUpperLimit	0.2
	TickSize	1
	LotSize	1
Iceberg	7	3	1	5	5	SELL	1	---	0
NewOrderRs	Eliminated
	Trades	0
	Orders	3
	Order	Limit	6	3	2	4	6	SELL	0	---	0
	Order	Limit	1	1	7	8	5	SELL	0	---	0
	Order	Limit	3	1	1	9	1	SELL	0	---	0
	Credits	7
	Credit	1	8
	Credit	2	6
	Credit	3	5
	Credit	4	8
	Credit	5	11
	Credit	6	12
	Credit	7	4
	Ownerships	7
	Ownership	1	25
	Ownership	2	49
	Ownership	3	29
	Ownership	4	19
	Ownership	5	52
	Ownership	6	94
	Ownership	7	83
	ReferencePrice	5
	StaticPriceBandLowerLimit	0.6
	StaticPriceBandUpperLimit	0.8
	TotalShares	100
	OwnershipUpperLimit	0.2
	TickSize	1
	LotSize	1
Limit	8	6	3	1	2	SELL	2	---	0
NewOrderRs	Rejected
	Trades	0
	Orders	3
	Order	Limit	6	3	2	4	6	SELL	0	---	0
	Order	Limit	1	1	7	8	5	SELL	0	---	0
	Order	Limit	3	1	1	9	1	SELL	0	---	0
	Credits	7
	Credit	1	8
	Credit	2	6
	Credit	3	5
	Credit	4	8
	Credit	5	11
	Credit	6	12
	Credit	7	4
	Ownerships	7
	Ownership	1	25
	Ownership	2	49
	Ownership	3	29
	Ownership	4	19
	Ownership	5	52
	Ownership	6	94
	Ownership	7	83
	ReferencePrice	5
	StaticPriceBandLowerLimit	0.6
	StaticPriceBandUpperLimit	0.8
	TotalShares	100
	OwnershipUpperLimit	0.2
	TickSize	1
	LotSize	1
Limit	9	6	3	2	7	SELL	0	---	0
NewOrderRs	Accepted
	Trades	0
	Orders	4
	Order	Limit	9	6	3	2	7	SELL	0	---	0
	Order	Limit	6	3	2	4	6	SELL	0	---	0
	Order	Limit	1	1	7	8	5	SELL	0	---	0
	Order	Limit	3	1	1	9	1	SELL	0	---	0
	Credits	7
	Credit	1	8
	Credit	2	6
	Credit	3	5
	Credit	4	8
	Credit	5	11
	Credit	6	12
	Credit	7	4
	Ownerships	7
	Ownership	1	25
	Ownership	2	49
	Ownership	3	29
	Ownership	4	19
	Ownership	5	52
	Ownership	6	94
	Ownership	7	83
	ReferencePrice	5
	StaticPriceBandLowerLimit	0.6
	StaticPriceBandUpperLimit	0.8
	TotalShares	100
	OwnershipUpperLimit	0.2
	TickSize	1
	LotSize	1
Iceberg	10	6	3	7	6	SELL	1	---	0
ReplaceOrderRs	Rejected
	Trades	0
	Orders	4
	Order	Limit	9	6	3	2	7	SELL	0	---	0
	Order	Limit	6	3	2	4	6	SELL	0	---	0
	Order	Limit	1	1	7	8	5	SELL	0	---	0
	Order	Limit	3	1	1	9	1	SELL	0	---	0
	Credits	7
	Credit	1	8
	Credit	2	6
	Credit	3	5
	Credit	4	8
	Credit	5	11
	Credit	6	12
	Credit	7	4
	Ownerships	7
	Ownership	1	25
	Ownership	2	49
	Ownership	3	29
	Ownership	4	19
	Ownership	5	52
	Ownership	6	94
	Ownership	7	83
	ReferencePrice	5
	StaticPriceBandLowerLimit	0.6
	StaticPriceBandUpperLimit	0.8
	TotalShares	100
	OwnershipUpperLimit	0.2
	TickSize	1
	LotSize	1
Limit	11	3	7	4	7	SELL	0	FAK	0
NewOrderRs	Eliminated
	Trades	0
	Orders	4
	Order	Limit	9	6	3	2	7	SELL	0	---	0
	Order	Limit	6	3	2	4	6	SELL	0	---	0
	Order	Limit	1	1	7	8	5	SELL	0	---	0
	Order	Limit	3	1	1	9	1	SELL	0	---	0
	Credits	7
	Credit	1	8
	Credit	2	6
	Credit	3	5
	Credit	4	8
	Credit	5	11
	Credit	6	12
	Credit	7	4
	Ownerships	7
	Ownership	1	25
	Ownership	2	49
	Ownership	3	29
	Ownership	4	19
	Ownership	5	52
	Ownership	6	94
	Ownership	7	83
	ReferencePrice	5
	StaticPriceBandLowerLimit	0.6
	StaticPriceBandUpperLimit	0.8
	TotalShares	100
	OwnershipUpperLimit	0.2
	TickSize	1
	LotSize	1
Limit	12	6	4	2	4	SELL	0	---	0
NewOrderRs	Accepted
	Trades	0
	Orders	5
	Order	Limit	9	6	3	2	7	SELL	0	---	0
	Order	Limit	12	6	4	2	4	SELL	0	---	0
	Order	Limit	6	3	2	4	6	SELL	0	---	0
	Order	Limit	1	1	7	8	5	SELL	0	---	0
	Order	Limit	3	1	1	9	1	SELL	0	---	0
	Credits	7
	Credit	1	8
	Credit	2	6
	Credit	3	5
	Credit	4	8
	Credit	5	11
	Credit	6	12
	Credit	7	4
	Ownerships	7
	Ownership	1	25
	Ownership	2	49
	Ownership	3	29
	Ownership	4	19
	Ownership	5	52
	Ownership	6	94
	Ownership	7	83
	ReferencePrice	5
	StaticPriceBandLowerLimit	0.6
	StaticPriceBandUpperLimit	0.8
	TotalShares	100
	OwnershipUpperLimit	0.2
	TickSize	1
	LotSize	1
Limit	13	1	3	7	2	BUY 	1	---	0
NewOrderRs	Rejected
	Trades	0
	Orders	5
	Order	Limit	9	6	3	2	7	SELL	0	---	0
	Order	Limit	12	6	4	2	4	SELL	0	---	0
	Order	Limit	6	3	2	4	6	SELL	0	---	0
	Order	Limit	1	1	7	8	5	SELL	0	---	0
	Order	Limit	3	1	1	9	1	SELL	0	---	0
	Credits	7
	Credit	1	8
	Credit	2	6
	Credit	3	5
	Credit	4	8
	Credit	5	11
	Credit	6	12
	Credit	7	4
	Ownerships	7
	Ownership	1	25
	Ownership	2	49
	Ownership	3	29
	Ownership	4	19
	Ownership	5	52
	Ownership	6	94
	Ownership	7	83
	ReferencePrice	5
	StaticPriceBandLowerLimit	0.6
	StaticPriceBandUpperLimit	0.8
	TotalShares	100
	OwnershipUpperLimit	0.2
	TickSize	1
	LotSize	1
Limit	14	1	2	4	6	BUY 	0	---	0
NewOrderRs	Rejected
	Trades	0
	Orders	5
	Order	Limit	9	6	3	2	7	SELL	0	---	0
	Order	Limit	12	6	4	2	4	SELL	0	---	0
	Order	Limit	6	3	2	4	6	SELL	0	---	0
	Order	Limit	1	1	7	8	5	SELL	0	---	0
	Order	Limit	3	1	1	9	1	SELL	0	---	0
	Credits	7
	Credit	1	8
	Credit	2	6
	Credit	3	5
	Credit	4	8
	Credit	5	11
	Credit	6	12
	Credit	7	4
	Ownerships	7
	Ownership	1	25
	Ownership	2	49
	Ownership	3	29
	Ownership	4	19
	Ownership	5	52
	Ownership	6	94
	Ownership	7	83
	ReferencePrice	5
	StaticPriceBandLowerLimit	0.6
	StaticPriceBandUpperLimit	0.8
	TotalShares	100
	OwnershipUpperLimit	0.2
	TickSize	1
	LotSize	1
CancelOrderRs	Rejected
	Orders	5
	Order	Limit	9	6	3	2	7	SELL	0	---	0
	Order	Limit	12	6	4	2	4	SELL	0	---	0
	Order	Limit	6	3	2	4	6	SELL	0	---	0
	Order	Limit	1	1	7	8	5	SELL	0	---	0
	Order	Limit	3	1	1	9	1	SELL	0	---	0
	Credits	7
	Credit	1	8
	Credit	2	6
	Credit	3	5
	Credit	4	8
	Credit	5	11
	Credit	6	12
	Credit	7	4
	Ownerships	7
