reported_result/report-8/ART_TFC/output/output5.txt

Limit	1	3	4	3	2	SELL	0	---	0
NewOrderRs	Accepted
	Trades	0
	Orders	1
	Order	Limit	1	3	4	3	2	SELL	0	---	0
	Credits	7
	Credit	1	13
	Credit	2	11
	Credit	3	16
	Credit	4	13
	Credit	5	8
	Credit	6	7
	Credit	7	12
	Ownerships	7
	Ownership	1	60
	Ownership	2	68
	Ownership	3	23
	Ownership	4	53
	Ownership	5	61
	Ownership	6	28
	Ownership	7	15
	ReferencePrice	5
	StaticPriceBandLowerLimit	0.6
	StaticPriceBandUpperLimit	0.8
	TotalShares	100
	OwnershipUpperLimit	0.2
	TickSize	1
	LotSize	1
Limit	2	1	5	2	3	BUY 	0	FAK	0
NewOrderRs	Rejected
	Trades	0
	Orders	1
	Order	Limit	1	3	4	3	2	SELL	0	---	0
	Credits	7
	Credit	1	13
	Credit	2	11
	Credit	3	16
	Credit	4	13
	Credit	5	8
	Credit	6	7
	Credit	7	12
	Ownerships	7
	Ownership	1	60
	Ownership	2	68
	Ownership	3	23
	Ownership	4	53
	Ownership	5	61
	Ownership	6	28
	Ownership	7	15
	ReferencePrice	5
	StaticPriceBandLowerLimit	0.6
	StaticPriceBandUpperLimit	0.8
	TotalShares	100
	OwnershipUpperLimit	0.2
	TickSize	1
	LotSize	1
Limit	3	3	5	6	2	BUY 	0	FAK	0
NewOrderRs	Rejected
	Trades	0
	Orders	1
	Order	Limit	1	3	4	3	2	SELL	0	---	0
	Credits	7
	Credit	1	13
	Credit	2	11
	Credit	3	16
	Credit	4	13
	Credit	5	8
	Credit	6	7
	Credit	7	12
	Ownerships	7
	Ownership	1	60
	Ownership	2	68
	Ownership	3	23
	Ownership	4	53
	Ownership	5	61
	Ownership	6	28
	Ownership	7	15
	ReferencePrice	5
	StaticPriceBandLowerLimit	0.6
	StaticPriceBandUpperLimit	0.8
	TotalShares	100
	OwnershipUpperLimit	0.2
	TickSize	1
	LotSize	1
Limit	4	2	1	5	8	SELL	4	---	0
NewOrderRs	Eliminated
	Trades	0
	Orders	1
	Order	Limit	1	3	4	3	2	SELL	0	---	0
	Credits	7
	Credit	1	13
	Credit	2	11
	Credit	3	16
	Credit	4	13
	Credit	5	8
	Credit	6	7
	Credit	7	12
	Ownerships	7
	Ownership	1	60
	Ownership	2	68
	Ownership	3	23
	Ownership	4	53
	Ownership	5	61
	Ownership	6	28
	Ownership	7	15
	ReferencePrice	5
	StaticPriceBandLowerLimit	0.6
	StaticPriceBandUpperLimit	0.8
	TotalShares	100
	OwnershipUpperLimit	0.2
	TickSize	1
	LotSize	1
CancelOrderRs	Rejected
	Orders	1
	Order	Limit	1	3	4	3	2	SELL	0	---	0
	Credits	7
	Credit	1	13
	Credit	2	11
	Credit	3	16
	Credit	4	13
	Credit	5	8
	Credit	6	7
	Credit	7	12
	Ownerships	7
	Ownership	1	60
	Ownership	2	68
	Ownership	3	23
	Ownership	4	53
	Ownership	5	61
	Ownership	6	28
	Ownership	7	15
	ReferencePrice	5
	StaticPriceBandLowerLimit	0.6
	StaticPriceBandUpperLimit	0.8
	TotalShares	100
	OwnershipUpperLimit	0.2
	TickSize	1
	LotSize	1
Limit	6	3	4	6	8	BUY 	0	FAK	0
NewOrderRs	Rejected
	Trades	0
	Orders	1
	Order	Limit	1	3	4	3	2	SELL	0	---	0
	Credits	7
	Credit	1	13
	Credit	2	11
	Credit	3	16
	Credit	4	13
	Credit	5	8
	Credit	6	7
	Credit	7	12
	Ownerships	7
	Ownership	1	60
	Ownership	2	68
	Ownership	3	23
	Ownership	4	53
	Ownership	5	61
	Ownership	6	28
	Ownership	7	15
	ReferencePrice	5
	StaticPriceBandLowerLimit	0.6
	StaticPriceBandUpperLimit	0.8
	TotalShares	100
	OwnershipUpperLimit	0.2
	TickSize	1
	LotSize	1
Limit	7	7	4	1	2	SELL	0	FAK	0
NewOrderRs	Rejected
	Trades	0
	Orders	1
	Order	Limit	1	3	4	3	2	SELL	0	---	0
	Credits	7
	Credit	1	13
	Credit	2	11
	Credit	3	16
	Credit	4	13
	Credit	5	8
	Credit	6	7
	Credit	7	12
	Ownerships	7
	Ownership	1	60
	Ownership	2	68
	Ownership	3	23
	Ownership	4	53
	Ownership	5	61
	Ownership	6	28
	Ownership	7	15
	ReferencePrice	5
	StaticPriceBandLowerLimit	0.6
	StaticPriceBandUpperLimit	0.8
	TotalShares	100
	OwnershipUpperLimit	0.2
	TickSize	1
	LotSize	1
Iceberg	8	4	3	7	2	SELL	0	---	0
NewOrderRs	Accepted
	Trades	0
	Orders	2
	Order	Limit	1	3	4	3	2	SELL	0	---	0
	Order	Iceberg	8	4	3	7	2	SELL	0	---	1
	Credits	7
	Credit	1	13
	Credit	2	11
	Credit	3	16
	Credit	4	13
	Credit	5	8
	Credit	6	7
	Credit	7	12
	Ownerships	7
	Ownership	1	60
	Ownership	2	68
	Ownership	3	23
	Ownership	4	53
	Ownership	5	61
	Ownership	6	28
	Ownership	7	15
	ReferencePrice	5
	StaticPriceBandLowerLimit	0.6
	StaticPriceBandUpperLimit	0.8
	TotalShares	100
	OwnershipUpperLimit	0.2
	TickSize	1
	LotSize	1
Limit	9	4	4	4	2	SELL	0	---	0
NewOrderRs	Accepted
	Trades	0
	Orders	3
	Order	Limit	1	3	4	3	2	SELL	0	---	0
	Order	Limit	9	4	4	4	2	SELL	0	---	0
	Order	Iceberg	8	4	3	7	2	SELL	0	---	1
	Credits	7
	Credit	1	13
	Credit	2	11
	Credit	3	16
	Credit	4	13
	Credit	5	8
	Credit	6	7
	Credit	7	12
	Ownerships	7
	Ownership	1	60
	Ownership	2	68
	Ownership	3	23
	Ownership	4	53
	Ownership	5	61
	Ownership	6	28
	Ownership	7	15
	ReferencePrice	5
	StaticPriceBandLowerLimit	0.6
	StaticPriceBandUpperLimit	0.8
	TotalShares	100
	OwnershipUpperLimit	0.2
	TickSize	1
	LotSize	1
Limit	10	4	4	7	3	SELL	0	FAK	0
ReplaceOrderRs	Eliminated
	Trades	0
	Orders	2
	Order	Limit	1	3	4	3	2	SELL	0	---	0
	Order	Iceberg	8	4	3	7	2	SELL	0	---	1
	Credits	7
	Credit	1	13
	Credit	2	11
	Credit	3	16
	Credit	4	13
	Credit	5	8
	Credit	6	7
	Credit	7	12
	Ownerships	7
	Ownership	1	60
	Ownership	2	68
	Ownership	3	23
	Ownership	4	53
	Ownership	5	61
	Ownership	6	28
	Ownership	7	15
	ReferencePrice	5
	StaticPriceBandLowerLimit	0.6
	StaticPriceBandUpperLimit	0.8
	TotalShares	100
	OwnershipUpperLimit	0.2
	TickSize	1
	LotSize	1
Iceberg	11	4	1	6	2	SELL	0	---	0
NewOrderRs	Accepted
	Trades	0
	Orders	3
	Order	Limit	1	3	4	3	2	SELL	0	---	0
	Order	Iceberg	11	4	1	6	2	SELL	0	---	1
	Order	Iceberg	8	4	3	7	2	SELL	0	---	1
	Credits	7
	Credit	1	13
	Credit	2	11
	Credit	3	16
	Credit	4	13
	Credit	5	8
	Credit	6	7
	Credit	7	12
	Ownerships	7
	Ownership	1	60
	Ownership	2	68
	Ownership	3	23
	Ownership	4	53
	Ownership	5	61
	Ownership	6	28
	Ownership	7	15
	ReferencePrice	5
	StaticPriceBandLowerLimit	0.6
	StaticPriceBandUpperLimit	0.8
	TotalShares	100
	OwnershipUpperLimit	0.2
	TickSize	1
	LotSize	1
Limit	12	1	3	4	8	BUY 	0	---	0
NewOrderRs	Rejected
	Trades	0
	Orders	3
	Order	Limit	1	3	4	3	2	SELL	0	---	0
	Order	Iceberg	11	4	1	6	2	SELL	0	---	1
	Order	Iceberg	8	4	3	7	2	SELL	0	---	1
	Credits	7
	Credit	1	13
	Credit	2	11
	Credit	3	16
	Credit	4	13
	Credit	5	8
	Credit	6	7
	Credit	7	12
	Ownerships	7
	Ownership	1	60
	Ownership	2	68
	Ownership	3	23
	Ownership	4	53
	Ownership	5	61
	Ownership	6	28
	Ownership	7	15
	ReferencePrice	5
	StaticPriceBandLowerLimit	0.6
	StaticPriceBandUpperLimit	0.8
	TotalShares	100
	OwnershipUpperLimit	0.2
	TickSize	1
	LotSize	1
Limit	13	5	1	2	2	SELL	0	---	0
NewOrderRs	Accepted
	Trades	0
	Orders	4
	Order	Limit	13	5	1	2	2	SELL	0	---	0
	Order	Limit	1	3	4	3	2	SELL	0	---	0
	Order	Iceberg	11	4	1	6	2	SELL	0	---	1
	Order	Iceberg	8	4	3	7	2	SELL	0	---	1
	Credits	7
	Credit	1	13
	Credit	2	11
	Credit	3	16
	Credit	4	13
	Credit	5	8
	Credit	6	7
	Credit	7	12
	Ownerships	7
	Ownership	1	60
	Ownership	2	68
	Ownership	3	23
	Ownership	4	53
	Ownership	5	61
	Ownership	6	28
	Ownership	7	15
	ReferencePrice	5
	StaticPriceBandLowerLimit	0.6
	StaticPriceBandUpperLimit	0.8
	TotalShares	100
	OwnershipUpperLimit	0.2
	TickSize	1
	LotSize	1
Limit	14	1	4	8	7	SELL	0	FAK	0
NewOrderRs	Eliminated
	Trades	0
	Orders	4
	Order	Limit	13	5	1	2	2	SELL	0	---	0
	Order	Limit	1	3	4	3	2	SELL	0	---	0
	Order	Iceberg	11	4	1	6	2	SELL	0	---	1
	Order	Iceberg	8	4	3	7	2	SELL	0	---	1
	Credits	7
	Credit	1	13
	Credit	2	11
	Credit	3	16
	Credit	4	13
	Credit	5	8
	Credit	6	7
	Credit	7	12
	Ownerships	7
	Ownership	1	60
	Ownership	2	68
	Ownership	3	23
	Ownership	4	53
	Ownership	5	61
	Ownership	6	28
	Ownership	7	15
	ReferencePrice	5
	StaticPriceBandLowerLimit	0.6
	StaticPriceBandUpperLimit	0.8
	TotalShares	100
	OwnershipUpperLimit	0.2
	TickSize	1
	LotSize	1
CancelOrderRs	Rejected
	Orders	4
	Order	Limit	13	5	1	2	2	SELL	0	---	0
	Order	Limit	1	3	4	3	2	SELL	0	---	0
	Order	Iceberg	11	4	1	6	2	SELL	0	---	1
	Order	Iceberg	8	4	3	7	2	SELL	0	---	1
	Credits	7
	Credit	1	13
	Credit	2	11
	Credit	3	16
	Credit	4	13
	Credit	5	8
	Credit	6	7
	Credit	7	12
	Ownerships	7
	Ownership	1	60
	Ownership	2	68
	Ownership	3	23
	Ownership	4	53
	Ownership	5	61
	Ownership	6	28
	Ownership	7	15
	ReferencePrice	5
	StaticPriceBandLowerLimit	0.6
	StaticPriceBandUpperLimit	0.8
	TotalShares	100
	OwnershipUpperLimit	0.2
	TickSize	1
	LotSize	1
Limit	16	2	3	7	4	BUY 	0	FAK	0
NewOrderRs	Rejected
	Trades	0
	Orders	4
	Order	Limit	13	5	1	2	2	SELL	0	---	0
	Order	Limit	1	3	4	3	2	SELL	0	---	0
	Order	Iceberg	11	4	1	6	2	SELL	0	---	1
	Order	Iceberg	8	4	3	7	2	SELL	0	---	1
	Credits	7
	Credit	1	13
	Credit	2	11
	Credit	3	16
